<body bgcolor="#f0f0f8">
<table width="100%" cellspacing=0 cellpadding=2 border=0 summary="heading">
<tr bgcolor="#6622aa">
<td valign=bottom>&nbsp;<br>
<font color="#ffffff" face="helvetica, arial">&nbsp;<br><big><big><strong>AttributeError</strong></big></big></font></td
><td align=right valign=bottom
><font color="#ffffff" face="helvetica, arial">Python 3.10.14: /usr/bin/python<br>Thu Apr 24 19:59:01 2025</font></td></tr></table>
    
<p>A problem occurred in a Python script.  Here is the sequence of
function calls leading up to the error, in the order they occurred.</p>
<table width="100%" cellspacing=0 cellpadding=0 border=0>
<tr><td bgcolor="#d8bbff"><big>&nbsp;</big><a href="file:///home/donghank/webserv_exp/www/cgi-bin/upload.py">/home/donghank/webserv_exp/www/cgi-bin/upload.py</a> in <strong>&lt;module&gt;</strong></td></tr>
<tr><td><font color="#909090"><tt>&nbsp;&nbsp;<small>&nbsp;&nbsp;419</small>&nbsp;&nbsp;&nbsp;&nbsp;&nbsp;&nbsp;&nbsp;&nbsp;&nbsp;"upload_dir":&nbsp;upload_dir&nbsp;if&nbsp;'upload_dir'&nbsp;in&nbsp;locals()&nbsp;else&nbsp;"Not&nbsp;defined",<br>
</tt></font></td></tr>
<tr><td><font color="#909090"><tt>&nbsp;&nbsp;<small>&nbsp;&nbsp;420</small>&nbsp;&nbsp;&nbsp;&nbsp;&nbsp;&nbsp;&nbsp;&nbsp;&nbsp;"upload_dir_exists":&nbsp;os.path.exists(upload_dir)&nbsp;if&nbsp;'upload_dir'&nbsp;in&nbsp;locals()&nbsp;else&nbsp;"Unknown",<br>
</tt></font></td></tr>
<tr><td bgcolor="#ffccee"><tt>=&gt;<small>&nbsp;&nbsp;421</small>&nbsp;&nbsp;&nbsp;&nbsp;&nbsp;&nbsp;&nbsp;&nbsp;&nbsp;"traceback":&nbsp;cgitb.text(sys.exc_info())<br>
</tt></td></tr>
<tr><td><font color="#909090"><tt>&nbsp;&nbsp;<small>&nbsp;&nbsp;422</small>&nbsp;&nbsp;&nbsp;&nbsp;&nbsp;}<br>
</tt></font></td></tr>
<tr><td><font color="#909090"><tt>&nbsp;&nbsp;<small>&nbsp;&nbsp;423</small>&nbsp;<br>
</tt></font></td></tr>
<tr><td><small><font color="#909090"><strong>cgitb</strong>&nbsp;= &lt;module 'cgitb' from '/usr/lib/python3.10/cgitb.py'&gt;, cgitb.<strong>text</strong>&nbsp;= &lt;function text&gt;, <strong>sys</strong>&nbsp;= &lt;module 'sys' (built-in)&gt;, sys.<strong>exc_info</strong>&nbsp;= &lt;built-in function exc_info&gt;</font></small></td></tr></table>
<table width="100%" cellspacing=0 cellpadding=0 border=0>
<tr><td bgcolor="#d8bbff"><big>&nbsp;</big><a href="file:///usr/lib/python3.10/cgitb.py">/usr/lib/python3.10/cgitb.py</a> in <strong>text</strong>(einfo=(&lt;class 'FileNotFoundError'&gt;, FileNotFoundError(2, 'No such file or directory'), &lt;traceback object&gt;), context=5)</td></tr>
<tr><td><font color="#909090"><tt>&nbsp;&nbsp;<small>&nbsp;&nbsp;245</small>&nbsp;&nbsp;&nbsp;&nbsp;&nbsp;exception&nbsp;=&nbsp;['%s:&nbsp;%s'&nbsp;%&nbsp;(str(etype),&nbsp;str(evalue))]<br>
</tt></font></td></tr>
<tr><td><font color="#909090"><tt>&nbsp;&nbsp;<small>&nbsp;&nbsp;246</small>&nbsp;&nbsp;&nbsp;&nbsp;&nbsp;for&nbsp;name&nbsp;in&nbsp;dir(evalue):<br>
</tt></font></td></tr>
<tr><td bgcolor="#ffccee"><tt>=&gt;<small>&nbsp;&nbsp;247</small>&nbsp;&nbsp;&nbsp;&nbsp;&nbsp;&nbsp;&nbsp;&nbsp;&nbsp;value&nbsp;=&nbsp;pydoc.text.repr(getattr(evalue,&nbsp;name))<br>
</tt></td></tr>
<tr><td><font color="#909090"><tt>&nbsp;&nbsp;<small>&nbsp;&nbsp;248</small>&nbsp;&nbsp;&nbsp;&nbsp;&nbsp;&nbsp;&nbsp;&nbsp;&nbsp;exception.append('\n%s%s&nbsp;=&nbsp;%s'&nbsp;%&nbsp;("&nbsp;"*4,&nbsp;name,&nbsp;value))<br>
</tt></font></td></tr>
<tr><td><font color="#909090"><tt>&nbsp;&nbsp;<small>&nbsp;&nbsp;249</small>&nbsp;<br>
</tt></font></td></tr>
<tr><td><small><font color="#909090"><strong>value</strong>&nbsp;= "(2, 'No such file or directory')", <em>global</em> <strong>pydoc</strong>&nbsp;= &lt;module 'pydoc' from '/usr/lib/python3.10/pydoc.py'&gt;, pydoc.<strong>text</strong>&nbsp;= &lt;pydoc.TextDoc object&gt;, pydoc.text.<strong>repr</strong>&nbsp;= &lt;bound method Repr.repr of &lt;pydoc.TextRepr object&gt;&gt;, <em>builtin</em> <strong>getattr</strong>&nbsp;= &lt;built-in function getattr&gt;, <strong>evalue</strong>&nbsp;= FileNotFoundError(2, 'No such file or directory'), <strong>name</strong>&nbsp;= 'characters_written'</font></small></td></tr></table><p><strong>AttributeError</strong>: characters_written
<br><tt><small>&nbsp;&nbsp;&nbsp;&nbsp;&nbsp;</small>&nbsp;</tt>args&nbsp;=
('characters_written',)
<br><tt><small>&nbsp;&nbsp;&nbsp;&nbsp;&nbsp;</small>&nbsp;</tt>name&nbsp;=
'characters_written'
<br><tt><small>&nbsp;&nbsp;&nbsp;&nbsp;&nbsp;</small>&nbsp;</tt>obj&nbsp;=
FileNotFoundError(2, 'No such file or directory')
<br><tt><small>&nbsp;&nbsp;&nbsp;&nbsp;&nbsp;</small>&nbsp;</tt>with_traceback&nbsp;=
&lt;built-in method with_traceback of AttributeError object&gt;


<!-- The above is a description of an error in a Python program, formatted
     for a web browser because the 'cgitb' module was enabled.  In case you
     are not reading this in a web browser, here is the original traceback:

Traceback (most recent call last):
  File "/home/donghank/webserv_exp/./www/cgi-bin/upload.py", line 260, in &lt;module&gt;
    os.makedirs(upload_dir)
  File "/usr/lib/python3.10/os.py", line 225, in makedirs
    mkdir(name, mode)
FileNotFoundError: [Errno 2] No such file or directory: ''

During handling of the above exception, another exception occurred:

Traceback (most recent call last):
  File "/home/donghank/webserv_exp/./www/cgi-bin/upload.py", line 421, in &lt;module&gt;
    "traceback": cgitb.text(sys.exc_info())
  File "/usr/lib/python3.10/cgitb.py", line 247, in text
    value = pydoc.text.repr(getattr(evalue, name))
AttributeError: characters_written

-->
